Traceback (most recent call last):
  File "/home/jed/cu/numpde-23f/VENV/lib/python3.11/site-packages/jupyter_cache/executors/utils.py", line 58, in single_nb_execution
    executenb(
  File "/home/jed/cu/numpde-23f/VENV/lib/python3.11/site-packages/nbclient/client.py", line 1305, in execute
    return NotebookClient(nb=nb, resources=resources, km=km, **kwargs).execute()
           ^^^^^^^^^^^^^^^^^^^^^^^^^^^^^^^^^^^^^^^^^^^^^^^^^^^^^^^^^^^^^^^^^^^^^
  File "/home/jed/cu/numpde-23f/VENV/lib/python3.11/site-packages/jupyter_core/utils/__init__.py", line 166, in wrapped
    return loop.run_until_complete(inner)
           ^^^^^^^^^^^^^^^^^^^^^^^^^^^^^^
  File "/usr/lib/python3.11/asyncio/base_events.py", line 653, in run_until_complete
    return future.result()
           ^^^^^^^^^^^^^^^
  File "/home/jed/cu/numpde-23f/VENV/lib/python3.11/site-packages/nbclient/client.py", line 705, in async_execute
    await self.async_execute_cell(
  File "/home/jed/cu/numpde-23f/VENV/lib/python3.11/site-packages/nbclient/client.py", line 1058, in async_execute_cell
    await self._check_raise_for_error(cell, cell_index, exec_reply)
  File "/home/jed/cu/numpde-23f/VENV/lib/python3.11/site-packages/nbclient/client.py", line 914, in _check_raise_for_error
    raise CellExecutionError.from_cell_and_msg(cell, exec_reply_content)
nbclient.exceptions.CellExecutionError: An error occurred while executing the following cell:
------------------
wind = 100
x, L, rhs = advdiff_cheb(40, wind, one)
@show minimum(diff(x))
plot(x, L \ rhs, legend=:none, marker=:auto)
------------------


UndefVarError: `CosRange` not defined

Stacktrace:
 [1] advdiff_cheb(n::Int64, wind::Int64, rhsfunc::Function, leftbc::Tuple{Int64, typeof(zero)}, rightbc::Tuple{Int64, typeof(zero)})
   @ Main ./In[6]:2
 [2] advdiff_cheb(n::Int64, wind::Int64, rhsfunc::Function)
   @ Main ./In[6]:2
 [3] top-level scope
   @ In[7]:2

